# 捕获异常

可以同时`catch`多个异常

```java
catch (ExceptionA | ExeceptionB a){
    //todo
}
```

但是 `ExceptionA`和`ExeceptionB` 不能有继承关系，而且 这个引用`a` 看起来只有`Exception`里面的方法，需要判断实际类型，并强转。



### 异常转换

```java
try{
	throw  new IOException();
}catch (IOException e){
	throw new RuntimeException(e);
}
/*
Exception in thread "main" java.lang.RuntimeException: java.io.IOException
	at com.company.TestCatch.main(TestCatch.java:11)
Caused by: java.io.IOException
	at com.company.TestCatch.main(TestCatch.java:9)
*/
```

`Caused by`  表明 `RuntimeException`是由 `IOException` 转换来的，可以通过 `e.getCause()` 获得





### 异常抑制

```java
try{
    throw  new ArithmeticException();
}finally {
    throw  new IllegalArgumentException();
}
//IllegalArgumentException
```

`finally`中抛出的异常抑制了`try-catch`块中抛出的异常，将导致异常信息丢失。

如果需要保存被印制的异常，可以使用 `e.addSuppressed()` 这个方法，`try-resource` 使用的就是这样。

```java
public class Main {
    public static void main(String[] args) throws Exception {
        Exception origin = null;
        try {
            System.out.println(Integer.parseInt("abc"));
        } catch (Exception e) {
            origin = e;
            throw e;
        } finally {
            Exception e = new IllegalArgumentException();
            if (origin != null) {
                e.addSuppressed(origin);//加入后，可以通过getSuppressed方法获取，内部是一个list，所以可以保存多个。
            }
            throw e; 
        }
    }
}
/*
Exception in thread "main" java.lang.IllegalArgumentException 
    at Main.main(Main.java:11) 
    Suppressed: java.lang.NumberFormatException: For input string: "abc" 
        at java.base/java.lang.NumberFormatException.forInputString(NumberFormatException.java:68)
        ....
*/
```





